2018-06-14 12:20:03,498 - ERROR - app.py - log_exception - 1560 - Exception on /admin/terms/menu/ [GET]
Traceback (most recent call last):
  File "C:\Users\Administrator\Envs\my_env\lib\site-packages\flask\app.py", line 1982, in wsgi_app
    response = self.full_dispatch_request()
  File "C:\Users\Administrator\Envs\my_env\lib\site-packages\flask\app.py", line 1614, in full_dispatch_request
    rv = self.handle_user_exception(e)
  File "C:\Users\Administrator\Envs\my_env\lib\site-packages\flask\app.py", line 1517, in handle_user_exception
    reraise(exc_type, exc_value, tb)
  File "C:\Users\Administrator\Envs\my_env\lib\site-packages\flask\_compat.py", line 33, in reraise
    raise value
  File "C:\Users\Administrator\Envs\my_env\lib\site-packages\flask\app.py", line 1612, in full_dispatch_request
    rv = self.dispatch_request()
  File "C:\Users\Administrator\Envs\my_env\lib\site-packages\flask\app.py", line 1598, in dispatch_request
    return self.view_functions[rule.endpoint](**req.view_args)
  File "C:\Users\Administrator\Envs\my_env\lib\site-packages\flask\views.py", line 84, in view
    return self.dispatch_request(*args, **kwargs)
  File "C:\Users\Administrator\Envs\my_env\lib\site-packages\flask\views.py", line 149, in dispatch_request
    return meth(*args, **kwargs)
  File "D:\python_project\yxx_admin\apps\admin\controller\terms.py", line 144, in get
    select_category = TermTaxonomy.query.fiter(TermTaxonomy.id.in_(select_menu.menu_url)).all()
AttributeError: 'BaseQuery' object has no attribute 'fiter'
2018-06-14 13:13:56,134 - ERROR - app.py - log_exception - 1560 - Exception on /admin/terms/menu/ [GET]
Traceback (most recent call last):
  File "C:\Users\Administrator\Envs\my_env\lib\site-packages\flask\app.py", line 1982, in wsgi_app
    response = self.full_dispatch_request()
  File "C:\Users\Administrator\Envs\my_env\lib\site-packages\flask\app.py", line 1614, in full_dispatch_request
    rv = self.handle_user_exception(e)
  File "C:\Users\Administrator\Envs\my_env\lib\site-packages\flask\app.py", line 1517, in handle_user_exception
    reraise(exc_type, exc_value, tb)
  File "C:\Users\Administrator\Envs\my_env\lib\site-packages\flask\_compat.py", line 33, in reraise
    raise value
  File "C:\Users\Administrator\Envs\my_env\lib\site-packages\flask\app.py", line 1612, in full_dispatch_request
    rv = self.dispatch_request()
  File "C:\Users\Administrator\Envs\my_env\lib\site-packages\flask\app.py", line 1598, in dispatch_request
    return self.view_functions[rule.endpoint](**req.view_args)
  File "C:\Users\Administrator\Envs\my_env\lib\site-packages\flask\views.py", line 84, in view
    return self.dispatch_request(*args, **kwargs)
  File "C:\Users\Administrator\Envs\my_env\lib\site-packages\flask\views.py", line 149, in dispatch_request
    return meth(*args, **kwargs)
  File "D:\python_project\yxx_admin\apps\admin\controller\terms.py", line 155, in get
    d['type'] = 'posts'
TypeError: list indices must be integers or slices, not str
2018-06-14 13:14:27,561 - ERROR - app.py - log_exception - 1560 - Exception on /admin/terms/menu/ [GET]
Traceback (most recent call last):
  File "C:\Users\Administrator\Envs\my_env\lib\site-packages\flask\app.py", line 1982, in wsgi_app
    response = self.full_dispatch_request()
  File "C:\Users\Administrator\Envs\my_env\lib\site-packages\flask\app.py", line 1614, in full_dispatch_request
    rv = self.handle_user_exception(e)
  File "C:\Users\Administrator\Envs\my_env\lib\site-packages\flask\app.py", line 1517, in handle_user_exception
    reraise(exc_type, exc_value, tb)
  File "C:\Users\Administrator\Envs\my_env\lib\site-packages\flask\_compat.py", line 33, in reraise
    raise value
  File "C:\Users\Administrator\Envs\my_env\lib\site-packages\flask\app.py", line 1612, in full_dispatch_request
    rv = self.dispatch_request()
  File "C:\Users\Administrator\Envs\my_env\lib\site-packages\flask\app.py", line 1598, in dispatch_request
    return self.view_functions[rule.endpoint](**req.view_args)
  File "C:\Users\Administrator\Envs\my_env\lib\site-packages\flask\views.py", line 84, in view
    return self.dispatch_request(*args, **kwargs)
  File "C:\Users\Administrator\Envs\my_env\lib\site-packages\flask\views.py", line 149, in dispatch_request
    return meth(*args, **kwargs)
  File "D:\python_project\yxx_admin\apps\admin\controller\terms.py", line 159, in get
    d['title'] = p.title
AttributeError: 'Posts' object has no attribute 'title'
2018-06-14 13:14:43,298 - ERROR - app.py - log_exception - 1560 - Exception on /admin/terms/menu/ [GET]
Traceback (most recent call last):
  File "C:\Users\Administrator\Envs\my_env\lib\site-packages\flask\app.py", line 1982, in wsgi_app
    response = self.full_dispatch_request()
  File "C:\Users\Administrator\Envs\my_env\lib\site-packages\flask\app.py", line 1614, in full_dispatch_request
    rv = self.handle_user_exception(e)
  File "C:\Users\Administrator\Envs\my_env\lib\site-packages\flask\app.py", line 1517, in handle_user_exception
    reraise(exc_type, exc_value, tb)
  File "C:\Users\Administrator\Envs\my_env\lib\site-packages\flask\_compat.py", line 33, in reraise
    raise value
  File "C:\Users\Administrator\Envs\my_env\lib\site-packages\flask\app.py", line 1612, in full_dispatch_request
    rv = self.dispatch_request()
  File "C:\Users\Administrator\Envs\my_env\lib\site-packages\flask\app.py", line 1598, in dispatch_request
    return self.view_functions[rule.endpoint](**req.view_args)
  File "C:\Users\Administrator\Envs\my_env\lib\site-packages\flask\views.py", line 84, in view
    return self.dispatch_request(*args, **kwargs)
  File "C:\Users\Administrator\Envs\my_env\lib\site-packages\flask\views.py", line 149, in dispatch_request
    return meth(*args, **kwargs)
  File "D:\python_project\yxx_admin\apps\admin\controller\terms.py", line 159, in get
    d['title'] = p.posts_title
AttributeError: 'Posts' object has no attribute 'posts_title'
2018-06-14 13:14:53,792 - ERROR - app.py - log_exception - 1560 - Exception on /admin/terms/menu/ [GET]
Traceback (most recent call last):
  File "C:\Users\Administrator\Envs\my_env\lib\site-packages\flask\app.py", line 1982, in wsgi_app
    response = self.full_dispatch_request()
  File "C:\Users\Administrator\Envs\my_env\lib\site-packages\flask\app.py", line 1614, in full_dispatch_request
    rv = self.handle_user_exception(e)
  File "C:\Users\Administrator\Envs\my_env\lib\site-packages\flask\app.py", line 1517, in handle_user_exception
    reraise(exc_type, exc_value, tb)
  File "C:\Users\Administrator\Envs\my_env\lib\site-packages\flask\_compat.py", line 33, in reraise
    raise value
  File "C:\Users\Administrator\Envs\my_env\lib\site-packages\flask\app.py", line 1612, in full_dispatch_request
    rv = self.dispatch_request()
  File "C:\Users\Administrator\Envs\my_env\lib\site-packages\flask\app.py", line 1598, in dispatch_request
    return self.view_functions[rule.endpoint](**req.view_args)
  File "C:\Users\Administrator\Envs\my_env\lib\site-packages\flask\views.py", line 84, in view
    return self.dispatch_request(*args, **kwargs)
  File "C:\Users\Administrator\Envs\my_env\lib\site-packages\flask\views.py", line 149, in dispatch_request
    return meth(*args, **kwargs)
  File "D:\python_project\yxx_admin\apps\admin\controller\terms.py", line 164, in get
    if c.slug:
AttributeError: 'list' object has no attribute 'slug'
2018-06-14 13:15:25,824 - ERROR - app.py - log_exception - 1560 - Exception on /admin/terms/menu/ [GET]
Traceback (most recent call last):
  File "C:\Users\Administrator\Envs\my_env\lib\site-packages\flask\app.py", line 1982, in wsgi_app
    response = self.full_dispatch_request()
  File "C:\Users\Administrator\Envs\my_env\lib\site-packages\flask\app.py", line 1614, in full_dispatch_request
    rv = self.handle_user_exception(e)
  File "C:\Users\Administrator\Envs\my_env\lib\site-packages\flask\app.py", line 1517, in handle_user_exception
    reraise(exc_type, exc_value, tb)
  File "C:\Users\Administrator\Envs\my_env\lib\site-packages\flask\_compat.py", line 33, in reraise
    raise value
  File "C:\Users\Administrator\Envs\my_env\lib\site-packages\flask\app.py", line 1612, in full_dispatch_request
    rv = self.dispatch_request()
  File "C:\Users\Administrator\Envs\my_env\lib\site-packages\flask\app.py", line 1598, in dispatch_request
    return self.view_functions[rule.endpoint](**req.view_args)
  File "C:\Users\Administrator\Envs\my_env\lib\site-packages\flask\views.py", line 84, in view
    return self.dispatch_request(*args, **kwargs)
  File "C:\Users\Administrator\Envs\my_env\lib\site-packages\flask\views.py", line 149, in dispatch_request
    return meth(*args, **kwargs)
  File "D:\python_project\yxx_admin\apps\admin\controller\terms.py", line 164, in get
    if c.slug:
AttributeError: 'list' object has no attribute 'slug'
2018-06-14 13:15:55,192 - ERROR - app.py - log_exception - 1560 - Exception on /admin/terms/menu/ [GET]
Traceback (most recent call last):
  File "C:\Users\Administrator\Envs\my_env\lib\site-packages\flask\app.py", line 1982, in wsgi_app
    response = self.full_dispatch_request()
  File "C:\Users\Administrator\Envs\my_env\lib\site-packages\flask\app.py", line 1614, in full_dispatch_request
    rv = self.handle_user_exception(e)
  File "C:\Users\Administrator\Envs\my_env\lib\site-packages\flask\app.py", line 1517, in handle_user_exception
    reraise(exc_type, exc_value, tb)
  File "C:\Users\Administrator\Envs\my_env\lib\site-packages\flask\_compat.py", line 33, in reraise
    raise value
  File "C:\Users\Administrator\Envs\my_env\lib\site-packages\flask\app.py", line 1612, in full_dispatch_request
    rv = self.dispatch_request()
  File "C:\Users\Administrator\Envs\my_env\lib\site-packages\flask\app.py", line 1598, in dispatch_request
    return self.view_functions[rule.endpoint](**req.view_args)
  File "C:\Users\Administrator\Envs\my_env\lib\site-packages\flask\views.py", line 84, in view
    return self.dispatch_request(*args, **kwargs)
  File "C:\Users\Administrator\Envs\my_env\lib\site-packages\flask\views.py", line 149, in dispatch_request
    return meth(*args, **kwargs)
  File "D:\python_project\yxx_admin\apps\admin\controller\terms.py", line 164, in get
    if c.terms[0].slug:
AttributeError: 'list' object has no attribute 'terms'
2018-06-14 13:17:20,930 - ERROR - app.py - log_exception - 1560 - Exception on /admin/terms/menu/ [GET]
Traceback (most recent call last):
  File "C:\Users\Administrator\Envs\my_env\lib\site-packages\flask\app.py", line 1982, in wsgi_app
    response = self.full_dispatch_request()
  File "C:\Users\Administrator\Envs\my_env\lib\site-packages\flask\app.py", line 1614, in full_dispatch_request
    rv = self.handle_user_exception(e)
  File "C:\Users\Administrator\Envs\my_env\lib\site-packages\flask\app.py", line 1517, in handle_user_exception
    reraise(exc_type, exc_value, tb)
  File "C:\Users\Administrator\Envs\my_env\lib\site-packages\flask\_compat.py", line 33, in reraise
    raise value
  File "C:\Users\Administrator\Envs\my_env\lib\site-packages\flask\app.py", line 1612, in full_dispatch_request
    rv = self.dispatch_request()
  File "C:\Users\Administrator\Envs\my_env\lib\site-packages\flask\app.py", line 1598, in dispatch_request
    return self.view_functions[rule.endpoint](**req.view_args)
  File "C:\Users\Administrator\Envs\my_env\lib\site-packages\flask\views.py", line 84, in view
    return self.dispatch_request(*args, **kwargs)
  File "C:\Users\Administrator\Envs\my_env\lib\site-packages\flask\views.py", line 149, in dispatch_request
    return meth(*args, **kwargs)
  File "D:\python_project\yxx_admin\apps\admin\controller\terms.py", line 164, in get
    if c.terms[0].slug:
AttributeError: 'list' object has no attribute 'terms'
2018-06-14 13:17:56,706 - ERROR - app.py - log_exception - 1560 - Exception on /admin/terms/menu/ [GET]
Traceback (most recent call last):
  File "C:\Users\Administrator\Envs\my_env\lib\site-packages\flask\app.py", line 1982, in wsgi_app
    response = self.full_dispatch_request()
  File "C:\Users\Administrator\Envs\my_env\lib\site-packages\flask\app.py", line 1614, in full_dispatch_request
    rv = self.handle_user_exception(e)
  File "C:\Users\Administrator\Envs\my_env\lib\site-packages\flask\app.py", line 1517, in handle_user_exception
    reraise(exc_type, exc_value, tb)
  File "C:\Users\Administrator\Envs\my_env\lib\site-packages\flask\_compat.py", line 33, in reraise
    raise value
  File "C:\Users\Administrator\Envs\my_env\lib\site-packages\flask\app.py", line 1612, in full_dispatch_request
    rv = self.dispatch_request()
  File "C:\Users\Administrator\Envs\my_env\lib\site-packages\flask\app.py", line 1598, in dispatch_request
    return self.view_functions[rule.endpoint](**req.view_args)
  File "C:\Users\Administrator\Envs\my_env\lib\site-packages\flask\views.py", line 84, in view
    return self.dispatch_request(*args, **kwargs)
  File "C:\Users\Administrator\Envs\my_env\lib\site-packages\flask\views.py", line 149, in dispatch_request
    return meth(*args, **kwargs)
  File "D:\python_project\yxx_admin\apps\admin\controller\terms.py", line 169, in get
    d['id'] = c.id
AttributeError: 'list' object has no attribute 'id'
2018-06-14 16:18:43,781 - ERROR - app.py - log_exception - 1560 - Exception on /admin/index/index/ [GET]
Traceback (most recent call last):
  File "C:\Users\Administrator\Envs\my_env\lib\site-packages\flask\app.py", line 1982, in wsgi_app
    response = self.full_dispatch_request()
  File "C:\Users\Administrator\Envs\my_env\lib\site-packages\flask\app.py", line 1614, in full_dispatch_request
    rv = self.handle_user_exception(e)
  File "C:\Users\Administrator\Envs\my_env\lib\site-packages\flask\app.py", line 1517, in handle_user_exception
    reraise(exc_type, exc_value, tb)
  File "C:\Users\Administrator\Envs\my_env\lib\site-packages\flask\_compat.py", line 33, in reraise
    raise value
  File "C:\Users\Administrator\Envs\my_env\lib\site-packages\flask\app.py", line 1612, in full_dispatch_request
    rv = self.dispatch_request()
  File "C:\Users\Administrator\Envs\my_env\lib\site-packages\flask\app.py", line 1598, in dispatch_request
    return self.view_functions[rule.endpoint](**req.view_args)
  File "D:\python_project\yxx_admin\apps\admin\controller\index.py", line 12, in index
    return  render_template('/admin/index/index.html',svemm=svemm,logins=logins,sysinfo=sysinfo)
  File "C:\Users\Administrator\Envs\my_env\lib\site-packages\flask\templating.py", line 134, in render_template
    context, ctx.app)
  File "C:\Users\Administrator\Envs\my_env\lib\site-packages\flask\templating.py", line 116, in _render
    rv = template.render(context)
  File "C:\Users\Administrator\Envs\my_env\lib\site-packages\jinja2\asyncsupport.py", line 76, in render
    return original_render(self, *args, **kwargs)
  File "C:\Users\Administrator\Envs\my_env\lib\site-packages\jinja2\environment.py", line 1008, in render
    return self.environment.handle_exception(exc_info, True)
  File "C:\Users\Administrator\Envs\my_env\lib\site-packages\jinja2\environment.py", line 780, in handle_exception
    reraise(exc_type, exc_value, tb)
  File "C:\Users\Administrator\Envs\my_env\lib\site-packages\jinja2\_compat.py", line 37, in reraise
    raise value.with_traceback(tb)
  File "D:\python_project\yxx_admin\templates\admin\index\index.html", line 1, in top-level template code
    {%  extends "admin/common/admin_base.html" %}
  File "D:\python_project\yxx_admin\templates\admin\common\admin_base.html", line 2, in top-level template code
    {%  extends "admin/common/base.html" %}
  File "D:\python_project\yxx_admin\templates\admin\common\base.html", line 32, in top-level template code
    {% block body%}{% endblock %}
  File "D:\python_project\yxx_admin\templates\admin\common\admin_base.html", line 171, in block "body"
    {% block content%}{% endblock %}
  File "D:\python_project\yxx_admin\templates\admin\index\index.html", line 77, in block "content"
    <img src="{{ no-img("") }}" alt="user image" class="online">
jinja2.exceptions.UndefinedError: 'img' is undefined
2018-06-14 19:03:52,097 - ERROR - app.py - log_exception - 1560 - Exception on / [GET]
Traceback (most recent call last):
  File "C:\Users\Administrator\Envs\my_env\lib\site-packages\flask\app.py", line 1982, in wsgi_app
    response = self.full_dispatch_request()
  File "C:\Users\Administrator\Envs\my_env\lib\site-packages\flask\app.py", line 1614, in full_dispatch_request
    rv = self.handle_user_exception(e)
  File "C:\Users\Administrator\Envs\my_env\lib\site-packages\flask\app.py", line 1517, in handle_user_exception
    reraise(exc_type, exc_value, tb)
  File "C:\Users\Administrator\Envs\my_env\lib\site-packages\flask\_compat.py", line 33, in reraise
    raise value
  File "C:\Users\Administrator\Envs\my_env\lib\site-packages\flask\app.py", line 1610, in full_dispatch_request
    rv = self.preprocess_request()
  File "C:\Users\Administrator\Envs\my_env\lib\site-packages\flask\app.py", line 1831, in preprocess_request
    rv = func()
  File "D:\python_project\yxx_admin\apps\home\hooks.py", line 10, in before_request
    menus = Terms.query(Terms.name == menu_name).first()
TypeError: 'BaseQuery' object is not callable
2018-06-14 19:04:27,735 - ERROR - app.py - log_exception - 1560 - Exception on / [GET]
Traceback (most recent call last):
  File "C:\Users\Administrator\Envs\my_env\lib\site-packages\flask\app.py", line 1982, in wsgi_app
    response = self.full_dispatch_request()
  File "C:\Users\Administrator\Envs\my_env\lib\site-packages\flask\app.py", line 1614, in full_dispatch_request
    rv = self.handle_user_exception(e)
  File "C:\Users\Administrator\Envs\my_env\lib\site-packages\flask\app.py", line 1517, in handle_user_exception
    reraise(exc_type, exc_value, tb)
  File "C:\Users\Administrator\Envs\my_env\lib\site-packages\flask\_compat.py", line 33, in reraise
    raise value
  File "C:\Users\Administrator\Envs\my_env\lib\site-packages\flask\app.py", line 1612, in full_dispatch_request
    rv = self.dispatch_request()
  File "C:\Users\Administrator\Envs\my_env\lib\site-packages\flask\app.py", line 1598, in dispatch_request
    return self.view_functions[rule.endpoint](**req.view_args)
  File "D:\python_project\yxx_admin\apps\home\controller\index.py", line 7, in index
    return render_template('/home/v1/index.html')
  File "C:\Users\Administrator\Envs\my_env\lib\site-packages\flask\templating.py", line 132, in render_template
    ctx.app.update_template_context(context)
  File "C:\Users\Administrator\Envs\my_env\lib\site-packages\flask\app.py", line 764, in update_template_context
    context.update(func())
TypeError: 'NoneType' object is not iterable
2018-06-14 19:04:49,290 - ERROR - app.py - log_exception - 1560 - Exception on / [GET]
Traceback (most recent call last):
  File "C:\Users\Administrator\Envs\my_env\lib\site-packages\flask\app.py", line 1982, in wsgi_app
    response = self.full_dispatch_request()
  File "C:\Users\Administrator\Envs\my_env\lib\site-packages\flask\app.py", line 1614, in full_dispatch_request
    rv = self.handle_user_exception(e)
  File "C:\Users\Administrator\Envs\my_env\lib\site-packages\flask\app.py", line 1517, in handle_user_exception
    reraise(exc_type, exc_value, tb)
  File "C:\Users\Administrator\Envs\my_env\lib\site-packages\flask\_compat.py", line 33, in reraise
    raise value
  File "C:\Users\Administrator\Envs\my_env\lib\site-packages\flask\app.py", line 1612, in full_dispatch_request
    rv = self.dispatch_request()
  File "C:\Users\Administrator\Envs\my_env\lib\site-packages\flask\app.py", line 1598, in dispatch_request
    return self.view_functions[rule.endpoint](**req.view_args)
  File "D:\python_project\yxx_admin\apps\home\controller\index.py", line 7, in index
    return render_template('/home/v1/index.html')
  File "C:\Users\Administrator\Envs\my_env\lib\site-packages\flask\templating.py", line 132, in render_template
    ctx.app.update_template_context(context)
  File "C:\Users\Administrator\Envs\my_env\lib\site-packages\flask\app.py", line 764, in update_template_context
    context.update(func())
TypeError: 'NoneType' object is not iterable
2018-06-14 19:32:29,109 - ERROR - app.py - log_exception - 1560 - Exception on / [GET]
Traceback (most recent call last):
  File "C:\Users\Administrator\Envs\my_env\lib\site-packages\flask\app.py", line 1982, in wsgi_app
    response = self.full_dispatch_request()
  File "C:\Users\Administrator\Envs\my_env\lib\site-packages\flask\app.py", line 1614, in full_dispatch_request
    rv = self.handle_user_exception(e)
  File "C:\Users\Administrator\Envs\my_env\lib\site-packages\flask\app.py", line 1517, in handle_user_exception
    reraise(exc_type, exc_value, tb)
  File "C:\Users\Administrator\Envs\my_env\lib\site-packages\flask\_compat.py", line 33, in reraise
    raise value
  File "C:\Users\Administrator\Envs\my_env\lib\site-packages\flask\app.py", line 1612, in full_dispatch_request
    rv = self.dispatch_request()
  File "C:\Users\Administrator\Envs\my_env\lib\site-packages\flask\app.py", line 1598, in dispatch_request
    return self.view_functions[rule.endpoint](**req.view_args)
  File "D:\python_project\yxx_admin\apps\home\controller\index.py", line 7, in index
    return render_template('/home/v1/index.html')
  File "C:\Users\Administrator\Envs\my_env\lib\site-packages\flask\templating.py", line 132, in render_template
    ctx.app.update_template_context(context)
  File "C:\Users\Administrator\Envs\my_env\lib\site-packages\flask\app.py", line 764, in update_template_context
    context.update(func())
TypeError: 'NoneType' object is not iterable
2018-06-14 19:32:59,580 - ERROR - app.py - log_exception - 1560 - Exception on / [GET]
Traceback (most recent call last):
  File "C:\Users\Administrator\Envs\my_env\lib\site-packages\flask\app.py", line 1982, in wsgi_app
    response = self.full_dispatch_request()
  File "C:\Users\Administrator\Envs\my_env\lib\site-packages\flask\app.py", line 1614, in full_dispatch_request
    rv = self.handle_user_exception(e)
  File "C:\Users\Administrator\Envs\my_env\lib\site-packages\flask\app.py", line 1517, in handle_user_exception
    reraise(exc_type, exc_value, tb)
  File "C:\Users\Administrator\Envs\my_env\lib\site-packages\flask\_compat.py", line 33, in reraise
    raise value
  File "C:\Users\Administrator\Envs\my_env\lib\site-packages\flask\app.py", line 1612, in full_dispatch_request
    rv = self.dispatch_request()
  File "C:\Users\Administrator\Envs\my_env\lib\site-packages\flask\app.py", line 1598, in dispatch_request
    return self.view_functions[rule.endpoint](**req.view_args)
  File "D:\python_project\yxx_admin\apps\home\controller\index.py", line 7, in index
    return render_template('/home/v1/index.html')
  File "C:\Users\Administrator\Envs\my_env\lib\site-packages\flask\templating.py", line 132, in render_template
    ctx.app.update_template_context(context)
  File "C:\Users\Administrator\Envs\my_env\lib\site-packages\flask\app.py", line 764, in update_template_context
    context.update(func())
TypeError: 'NoneType' object is not iterable
2018-06-14 19:33:11,391 - ERROR - app.py - log_exception - 1560 - Exception on / [GET]
Traceback (most recent call last):
  File "C:\Users\Administrator\Envs\my_env\lib\site-packages\flask\app.py", line 1982, in wsgi_app
    response = self.full_dispatch_request()
  File "C:\Users\Administrator\Envs\my_env\lib\site-packages\flask\app.py", line 1614, in full_dispatch_request
    rv = self.handle_user_exception(e)
  File "C:\Users\Administrator\Envs\my_env\lib\site-packages\flask\app.py", line 1517, in handle_user_exception
    reraise(exc_type, exc_value, tb)
  File "C:\Users\Administrator\Envs\my_env\lib\site-packages\flask\_compat.py", line 33, in reraise
    raise value
  File "C:\Users\Administrator\Envs\my_env\lib\site-packages\flask\app.py", line 1612, in full_dispatch_request
    rv = self.dispatch_request()
  File "C:\Users\Administrator\Envs\my_env\lib\site-packages\flask\app.py", line 1598, in dispatch_request
    return self.view_functions[rule.endpoint](**req.view_args)
  File "D:\python_project\yxx_admin\apps\home\controller\index.py", line 7, in index
    return render_template('/home/v1/index.html')
  File "C:\Users\Administrator\Envs\my_env\lib\site-packages\flask\templating.py", line 132, in render_template
    ctx.app.update_template_context(context)
  File "C:\Users\Administrator\Envs\my_env\lib\site-packages\flask\app.py", line 764, in update_template_context
    context.update(func())
TypeError: 'NoneType' object is not iterable
2018-06-14 19:33:15,480 - ERROR - app.py - log_exception - 1560 - Exception on / [GET]
Traceback (most recent call last):
  File "C:\Users\Administrator\Envs\my_env\lib\site-packages\flask\app.py", line 1982, in wsgi_app
    response = self.full_dispatch_request()
  File "C:\Users\Administrator\Envs\my_env\lib\site-packages\flask\app.py", line 1614, in full_dispatch_request
    rv = self.handle_user_exception(e)
  File "C:\Users\Administrator\Envs\my_env\lib\site-packages\flask\app.py", line 1517, in handle_user_exception
    reraise(exc_type, exc_value, tb)
  File "C:\Users\Administrator\Envs\my_env\lib\site-packages\flask\_compat.py", line 33, in reraise
    raise value
  File "C:\Users\Administrator\Envs\my_env\lib\site-packages\flask\app.py", line 1612, in full_dispatch_request
    rv = self.dispatch_request()
  File "C:\Users\Administrator\Envs\my_env\lib\site-packages\flask\app.py", line 1598, in dispatch_request
    return self.view_functions[rule.endpoint](**req.view_args)
  File "D:\python_project\yxx_admin\apps\home\controller\index.py", line 7, in index
    return render_template('/home/v1/index.html')
  File "C:\Users\Administrator\Envs\my_env\lib\site-packages\flask\templating.py", line 132, in render_template
    ctx.app.update_template_context(context)
  File "C:\Users\Administrator\Envs\my_env\lib\site-packages\flask\app.py", line 764, in update_template_context
    context.update(func())
TypeError: 'NoneType' object is not iterable
2018-06-14 19:33:37,954 - ERROR - app.py - log_exception - 1560 - Exception on / [GET]
Traceback (most recent call last):
  File "C:\Users\Administrator\Envs\my_env\lib\site-packages\flask\app.py", line 1982, in wsgi_app
    response = self.full_dispatch_request()
  File "C:\Users\Administrator\Envs\my_env\lib\site-packages\flask\app.py", line 1614, in full_dispatch_request
    rv = self.handle_user_exception(e)
  File "C:\Users\Administrator\Envs\my_env\lib\site-packages\flask\app.py", line 1517, in handle_user_exception
    reraise(exc_type, exc_value, tb)
  File "C:\Users\Administrator\Envs\my_env\lib\site-packages\flask\_compat.py", line 33, in reraise
    raise value
  File "C:\Users\Administrator\Envs\my_env\lib\site-packages\flask\app.py", line 1612, in full_dispatch_request
    rv = self.dispatch_request()
  File "C:\Users\Administrator\Envs\my_env\lib\site-packages\flask\app.py", line 1598, in dispatch_request
    return self.view_functions[rule.endpoint](**req.view_args)
  File "D:\python_project\yxx_admin\apps\home\controller\index.py", line 7, in index
    return render_template('/home/v1/index.html')
  File "C:\Users\Administrator\Envs\my_env\lib\site-packages\flask\templating.py", line 132, in render_template
    ctx.app.update_template_context(context)
  File "C:\Users\Administrator\Envs\my_env\lib\site-packages\flask\app.py", line 764, in update_template_context
    context.update(func())
TypeError: 'NoneType' object is not iterable
2018-06-14 19:33:47,931 - ERROR - app.py - log_exception - 1560 - Exception on / [GET]
Traceback (most recent call last):
  File "C:\Users\Administrator\Envs\my_env\lib\site-packages\flask\app.py", line 1982, in wsgi_app
    response = self.full_dispatch_request()
  File "C:\Users\Administrator\Envs\my_env\lib\site-packages\flask\app.py", line 1614, in full_dispatch_request
    rv = self.handle_user_exception(e)
  File "C:\Users\Administrator\Envs\my_env\lib\site-packages\flask\app.py", line 1517, in handle_user_exception
    reraise(exc_type, exc_value, tb)
  File "C:\Users\Administrator\Envs\my_env\lib\site-packages\flask\_compat.py", line 33, in reraise
    raise value
  File "C:\Users\Administrator\Envs\my_env\lib\site-packages\flask\app.py", line 1612, in full_dispatch_request
    rv = self.dispatch_request()
  File "C:\Users\Administrator\Envs\my_env\lib\site-packages\flask\app.py", line 1598, in dispatch_request
    return self.view_functions[rule.endpoint](**req.view_args)
  File "D:\python_project\yxx_admin\apps\home\controller\index.py", line 7, in index
    return render_template('/home/v1/index.html')
  File "C:\Users\Administrator\Envs\my_env\lib\site-packages\flask\templating.py", line 132, in render_template
    ctx.app.update_template_context(context)
  File "C:\Users\Administrator\Envs\my_env\lib\site-packages\flask\app.py", line 764, in update_template_context
    context.update(func())
TypeError: 'NoneType' object is not iterable
2018-06-14 19:34:12,341 - ERROR - app.py - log_exception - 1560 - Exception on / [GET]
Traceback (most recent call last):
  File "C:\Users\Administrator\Envs\my_env\lib\site-packages\flask\app.py", line 1982, in wsgi_app
    response = self.full_dispatch_request()
  File "C:\Users\Administrator\Envs\my_env\lib\site-packages\flask\app.py", line 1614, in full_dispatch_request
    rv = self.handle_user_exception(e)
  File "C:\Users\Administrator\Envs\my_env\lib\site-packages\flask\app.py", line 1517, in handle_user_exception
    reraise(exc_type, exc_value, tb)
  File "C:\Users\Administrator\Envs\my_env\lib\site-packages\flask\_compat.py", line 33, in reraise
    raise value
  File "C:\Users\Administrator\Envs\my_env\lib\site-packages\flask\app.py", line 1612, in full_dispatch_request
    rv = self.dispatch_request()
  File "C:\Users\Administrator\Envs\my_env\lib\site-packages\flask\app.py", line 1598, in dispatch_request
    return self.view_functions[rule.endpoint](**req.view_args)
  File "D:\python_project\yxx_admin\apps\home\controller\index.py", line 7, in index
    return render_template('/home/v1/index.html')
  File "C:\Users\Administrator\Envs\my_env\lib\site-packages\flask\templating.py", line 132, in render_template
    ctx.app.update_template_context(context)
  File "C:\Users\Administrator\Envs\my_env\lib\site-packages\flask\app.py", line 764, in update_template_context
    context.update(func())
TypeError: 'NoneType' object is not iterable
2018-06-14 19:35:02,932 - ERROR - app.py - log_exception - 1560 - Exception on / [GET]
Traceback (most recent call last):
  File "C:\Users\Administrator\Envs\my_env\lib\site-packages\flask\app.py", line 1982, in wsgi_app
    response = self.full_dispatch_request()
  File "C:\Users\Administrator\Envs\my_env\lib\site-packages\flask\app.py", line 1614, in full_dispatch_request
    rv = self.handle_user_exception(e)
  File "C:\Users\Administrator\Envs\my_env\lib\site-packages\flask\app.py", line 1517, in handle_user_exception
    reraise(exc_type, exc_value, tb)
  File "C:\Users\Administrator\Envs\my_env\lib\site-packages\flask\_compat.py", line 33, in reraise
    raise value
  File "C:\Users\Administrator\Envs\my_env\lib\site-packages\flask\app.py", line 1612, in full_dispatch_request
    rv = self.dispatch_request()
  File "C:\Users\Administrator\Envs\my_env\lib\site-packages\flask\app.py", line 1598, in dispatch_request
    return self.view_functions[rule.endpoint](**req.view_args)
  File "D:\python_project\yxx_admin\apps\home\controller\index.py", line 7, in index
    return render_template('/home/v1/index.html')
  File "C:\Users\Administrator\Envs\my_env\lib\site-packages\flask\templating.py", line 132, in render_template
    ctx.app.update_template_context(context)
  File "C:\Users\Administrator\Envs\my_env\lib\site-packages\flask\app.py", line 764, in update_template_context
    context.update(func())
TypeError: cannot convert dictionary update sequence element #0 to a sequence
2018-06-14 19:35:46,972 - ERROR - app.py - log_exception - 1560 - Exception on / [GET]
Traceback (most recent call last):
  File "C:\Users\Administrator\Envs\my_env\lib\site-packages\flask\app.py", line 1982, in wsgi_app
    response = self.full_dispatch_request()
  File "C:\Users\Administrator\Envs\my_env\lib\site-packages\flask\app.py", line 1614, in full_dispatch_request
    rv = self.handle_user_exception(e)
  File "C:\Users\Administrator\Envs\my_env\lib\site-packages\flask\app.py", line 1517, in handle_user_exception
    reraise(exc_type, exc_value, tb)
  File "C:\Users\Administrator\Envs\my_env\lib\site-packages\flask\_compat.py", line 33, in reraise
    raise value
  File "C:\Users\Administrator\Envs\my_env\lib\site-packages\flask\app.py", line 1612, in full_dispatch_request
    rv = self.dispatch_request()
  File "C:\Users\Administrator\Envs\my_env\lib\site-packages\flask\app.py", line 1598, in dispatch_request
    return self.view_functions[rule.endpoint](**req.view_args)
  File "D:\python_project\yxx_admin\apps\home\controller\index.py", line 7, in index
    return render_template('/home/v1/index.html')
  File "C:\Users\Administrator\Envs\my_env\lib\site-packages\flask\templating.py", line 132, in render_template
    ctx.app.update_template_context(context)
  File "C:\Users\Administrator\Envs\my_env\lib\site-packages\flask\app.py", line 764, in update_template_context
    context.update(func())
ValueError: dictionary update sequence element #0 has length 4; 2 is required
2018-06-14 19:36:27,620 - ERROR - app.py - log_exception - 1560 - Exception on / [GET]
Traceback (most recent call last):
  File "C:\Users\Administrator\Envs\my_env\lib\site-packages\flask\app.py", line 1982, in wsgi_app
    response = self.full_dispatch_request()
  File "C:\Users\Administrator\Envs\my_env\lib\site-packages\flask\app.py", line 1614, in full_dispatch_request
    rv = self.handle_user_exception(e)
  File "C:\Users\Administrator\Envs\my_env\lib\site-packages\flask\app.py", line 1517, in handle_user_exception
    reraise(exc_type, exc_value, tb)
  File "C:\Users\Administrator\Envs\my_env\lib\site-packages\flask\_compat.py", line 33, in reraise
    raise value
  File "C:\Users\Administrator\Envs\my_env\lib\site-packages\flask\app.py", line 1612, in full_dispatch_request
    rv = self.dispatch_request()
  File "C:\Users\Administrator\Envs\my_env\lib\site-packages\flask\app.py", line 1598, in dispatch_request
    return self.view_functions[rule.endpoint](**req.view_args)
  File "D:\python_project\yxx_admin\apps\home\controller\index.py", line 7, in index
    return render_template('/home/v1/index.html')
  File "C:\Users\Administrator\Envs\my_env\lib\site-packages\flask\templating.py", line 132, in render_template
    ctx.app.update_template_context(context)
  File "C:\Users\Administrator\Envs\my_env\lib\site-packages\flask\app.py", line 764, in update_template_context
    context.update(func())
TypeError: cannot convert dictionary update sequence element #0 to a sequence
2018-06-14 19:36:47,950 - ERROR - app.py - log_exception - 1560 - Exception on / [GET]
Traceback (most recent call last):
  File "C:\Users\Administrator\Envs\my_env\lib\site-packages\flask\app.py", line 1982, in wsgi_app
    response = self.full_dispatch_request()
  File "C:\Users\Administrator\Envs\my_env\lib\site-packages\flask\app.py", line 1614, in full_dispatch_request
    rv = self.handle_user_exception(e)
  File "C:\Users\Administrator\Envs\my_env\lib\site-packages\flask\app.py", line 1517, in handle_user_exception
    reraise(exc_type, exc_value, tb)
  File "C:\Users\Administrator\Envs\my_env\lib\site-packages\flask\_compat.py", line 33, in reraise
    raise value
  File "C:\Users\Administrator\Envs\my_env\lib\site-packages\flask\app.py", line 1612, in full_dispatch_request
    rv = self.dispatch_request()
  File "C:\Users\Administrator\Envs\my_env\lib\site-packages\flask\app.py", line 1598, in dispatch_request
    return self.view_functions[rule.endpoint](**req.view_args)
  File "D:\python_project\yxx_admin\apps\home\controller\index.py", line 7, in index
    return render_template('/home/v1/index.html')
  File "C:\Users\Administrator\Envs\my_env\lib\site-packages\flask\templating.py", line 132, in render_template
    ctx.app.update_template_context(context)
  File "C:\Users\Administrator\Envs\my_env\lib\site-packages\flask\app.py", line 764, in update_template_context
    context.update(func())
ValueError: dictionary update sequence element #0 has length 4; 2 is required
2018-06-14 19:39:08,891 - ERROR - app.py - log_exception - 1560 - Exception on / [GET]
Traceback (most recent call last):
  File "C:\Users\Administrator\Envs\my_env\lib\site-packages\flask\app.py", line 1982, in wsgi_app
    response = self.full_dispatch_request()
  File "C:\Users\Administrator\Envs\my_env\lib\site-packages\flask\app.py", line 1614, in full_dispatch_request
    rv = self.handle_user_exception(e)
  File "C:\Users\Administrator\Envs\my_env\lib\site-packages\flask\app.py", line 1517, in handle_user_exception
    reraise(exc_type, exc_value, tb)
  File "C:\Users\Administrator\Envs\my_env\lib\site-packages\flask\_compat.py", line 33, in reraise
    raise value
  File "C:\Users\Administrator\Envs\my_env\lib\site-packages\flask\app.py", line 1612, in full_dispatch_request
    rv = self.dispatch_request()
  File "C:\Users\Administrator\Envs\my_env\lib\site-packages\flask\app.py", line 1598, in dispatch_request
    return self.view_functions[rule.endpoint](**req.view_args)
  File "D:\python_project\yxx_admin\apps\home\controller\index.py", line 7, in index
    return render_template('/home/v1/index.html')
  File "C:\Users\Administrator\Envs\my_env\lib\site-packages\flask\templating.py", line 132, in render_template
    ctx.app.update_template_context(context)
  File "C:\Users\Administrator\Envs\my_env\lib\site-packages\flask\app.py", line 764, in update_template_context
    context.update(func())
  File "D:\python_project\yxx_admin\apps\home\hooks.py", line 18, in nav
    return {'test':m}
NameError: name 'm' is not defined
2018-06-14 19:41:14,454 - ERROR - app.py - log_exception - 1560 - Exception on / [GET]
Traceback (most recent call last):
  File "C:\Users\Administrator\Envs\my_env\lib\site-packages\flask\app.py", line 1982, in wsgi_app
    response = self.full_dispatch_request()
  File "C:\Users\Administrator\Envs\my_env\lib\site-packages\flask\app.py", line 1614, in full_dispatch_request
    rv = self.handle_user_exception(e)
  File "C:\Users\Administrator\Envs\my_env\lib\site-packages\flask\app.py", line 1517, in handle_user_exception
    reraise(exc_type, exc_value, tb)
  File "C:\Users\Administrator\Envs\my_env\lib\site-packages\flask\_compat.py", line 33, in reraise
    raise value
  File "C:\Users\Administrator\Envs\my_env\lib\site-packages\flask\app.py", line 1612, in full_dispatch_request
    rv = self.dispatch_request()
  File "C:\Users\Administrator\Envs\my_env\lib\site-packages\flask\app.py", line 1598, in dispatch_request
    return self.view_functions[rule.endpoint](**req.view_args)
  File "D:\python_project\yxx_admin\apps\home\controller\index.py", line 7, in index
    return render_template('/home/v1/index.html')
  File "C:\Users\Administrator\Envs\my_env\lib\site-packages\flask\templating.py", line 132, in render_template
    ctx.app.update_template_context(context)
  File "C:\Users\Administrator\Envs\my_env\lib\site-packages\flask\app.py", line 764, in update_template_context
    context.update(func())
  File "D:\python_project\yxx_admin\apps\home\hooks.py", line 19, in nav
    if tm.term_taxonomy.taxonomy == 3:
AttributeError: 'list' object has no attribute 'term_taxonomy'
2018-06-14 20:13:51,219 - ERROR - app.py - log_exception - 1560 - Exception on / [GET]
Traceback (most recent call last):
  File "C:\Users\Administrator\Envs\my_env\lib\site-packages\flask\app.py", line 1982, in wsgi_app
    response = self.full_dispatch_request()
  File "C:\Users\Administrator\Envs\my_env\lib\site-packages\flask\app.py", line 1614, in full_dispatch_request
    rv = self.handle_user_exception(e)
  File "C:\Users\Administrator\Envs\my_env\lib\site-packages\flask\app.py", line 1517, in handle_user_exception
    reraise(exc_type, exc_value, tb)
  File "C:\Users\Administrator\Envs\my_env\lib\site-packages\flask\_compat.py", line 33, in reraise
    raise value
  File "C:\Users\Administrator\Envs\my_env\lib\site-packages\flask\app.py", line 1612, in full_dispatch_request
    rv = self.dispatch_request()
  File "C:\Users\Administrator\Envs\my_env\lib\site-packages\flask\app.py", line 1598, in dispatch_request
    return self.view_functions[rule.endpoint](**req.view_args)
  File "D:\python_project\yxx_admin\apps\home\controller\index.py", line 7, in index
    return render_template('/home/v1/index.html')
  File "C:\Users\Administrator\Envs\my_env\lib\site-packages\flask\templating.py", line 132, in render_template
    ctx.app.update_template_context(context)
  File "C:\Users\Administrator\Envs\my_env\lib\site-packages\flask\app.py", line 764, in update_template_context
    context.update(func())
  File "D:\python_project\yxx_admin\apps\home\hooks.py", line 36, in nav
    n_child = TermTaxonomy.query.filter(TermTaxonomy)
  File "<string>", line 2, in filter
  File "C:\Users\Administrator\Envs\my_env\lib\site-packages\sqlalchemy\orm\base.py", line 201, in generate
    fn(self, *args[1:], **kw)
  File "C:\Users\Administrator\Envs\my_env\lib\site-packages\sqlalchemy\orm\query.py", line 1597, in filter
    criterion = expression._expression_literal_as_text(criterion)
  File "C:\Users\Administrator\Envs\my_env\lib\site-packages\sqlalchemy\sql\elements.py", line 4254, in _expression_literal_as_text
    return _literal_as_text(element, warn=True)
  File "C:\Users\Administrator\Envs\my_env\lib\site-packages\sqlalchemy\sql\elements.py", line 4275, in _literal_as_text
    "instead" % type(element)
sqlalchemy.exc.ArgumentError: SQL expression object or string expected, got object of type <class 'flask_sqlalchemy.model.DefaultMeta'> instead
2018-06-14 20:14:11,333 - ERROR - app.py - log_exception - 1560 - Exception on / [GET]
Traceback (most recent call last):
  File "C:\Users\Administrator\Envs\my_env\lib\site-packages\flask\app.py", line 1982, in wsgi_app
    response = self.full_dispatch_request()
  File "C:\Users\Administrator\Envs\my_env\lib\site-packages\flask\app.py", line 1614, in full_dispatch_request
    rv = self.handle_user_exception(e)
  File "C:\Users\Administrator\Envs\my_env\lib\site-packages\flask\app.py", line 1517, in handle_user_exception
    reraise(exc_type, exc_value, tb)
  File "C:\Users\Administrator\Envs\my_env\lib\site-packages\flask\_compat.py", line 33, in reraise
    raise value
  File "C:\Users\Administrator\Envs\my_env\lib\site-packages\flask\app.py", line 1612, in full_dispatch_request
    rv = self.dispatch_request()
  File "C:\Users\Administrator\Envs\my_env\lib\site-packages\flask\app.py", line 1598, in dispatch_request
    return self.view_functions[rule.endpoint](**req.view_args)
  File "D:\python_project\yxx_admin\apps\home\controller\index.py", line 7, in index
    return render_template('/home/v1/index.html')
  File "C:\Users\Administrator\Envs\my_env\lib\site-packages\flask\templating.py", line 132, in render_template
    ctx.app.update_template_context(context)
  File "C:\Users\Administrator\Envs\my_env\lib\site-packages\flask\app.py", line 764, in update_template_context
    context.update(func())
  File "D:\python_project\yxx_admin\apps\home\hooks.py", line 35, in nav
    n_child = TermTaxonomy.query.filter(TermTaxonomy)
  File "<string>", line 2, in filter
  File "C:\Users\Administrator\Envs\my_env\lib\site-packages\sqlalchemy\orm\base.py", line 201, in generate
    fn(self, *args[1:], **kw)
  File "C:\Users\Administrator\Envs\my_env\lib\site-packages\sqlalchemy\orm\query.py", line 1597, in filter
    criterion = expression._expression_literal_as_text(criterion)
  File "C:\Users\Administrator\Envs\my_env\lib\site-packages\sqlalchemy\sql\elements.py", line 4254, in _expression_literal_as_text
    return _literal_as_text(element, warn=True)
  File "C:\Users\Administrator\Envs\my_env\lib\site-packages\sqlalchemy\sql\elements.py", line 4275, in _literal_as_text
    "instead" % type(element)
sqlalchemy.exc.ArgumentError: SQL expression object or string expected, got object of type <class 'flask_sqlalchemy.model.DefaultMeta'> instead
2018-06-14 20:38:30,248 - ERROR - app.py - log_exception - 1560 - Exception on / [GET]
Traceback (most recent call last):
  File "C:\Users\Administrator\Envs\my_env\lib\site-packages\flask\app.py", line 1982, in wsgi_app
    response = self.full_dispatch_request()
  File "C:\Users\Administrator\Envs\my_env\lib\site-packages\flask\app.py", line 1614, in full_dispatch_request
    rv = self.handle_user_exception(e)
  File "C:\Users\Administrator\Envs\my_env\lib\site-packages\flask\app.py", line 1517, in handle_user_exception
    reraise(exc_type, exc_value, tb)
  File "C:\Users\Administrator\Envs\my_env\lib\site-packages\flask\_compat.py", line 33, in reraise
    raise value
  File "C:\Users\Administrator\Envs\my_env\lib\site-packages\flask\app.py", line 1612, in full_dispatch_request
    rv = self.dispatch_request()
  File "C:\Users\Administrator\Envs\my_env\lib\site-packages\flask\app.py", line 1598, in dispatch_request
    return self.view_functions[rule.endpoint](**req.view_args)
  File "D:\python_project\yxx_admin\apps\home\controller\index.py", line 7, in index
    return render_template('/home/v1/index.html')
  File "C:\Users\Administrator\Envs\my_env\lib\site-packages\flask\templating.py", line 132, in render_template
    ctx.app.update_template_context(context)
  File "C:\Users\Administrator\Envs\my_env\lib\site-packages\flask\app.py", line 764, in update_template_context
    context.update(func())
  File "D:\python_project\yxx_admin\apps\home\hooks.py", line 33, in nav
    print(n.get_pos)
AttributeError: 'TermTaxonomy' object has no attribute 'get_pos'
