2018-06-16 14:01:52,572 - ERROR - app.py - log_exception - 1560 - Exception on /ajax_get_comments/ [GET]
Traceback (most recent call last):
  File "C:\Users\lenovo\Envs\yxx_admin\lib\site-packages\flask\app.py", line 1982, in wsgi_app
    response = self.full_dispatch_request()
  File "C:\Users\lenovo\Envs\yxx_admin\lib\site-packages\flask\app.py", line 1614, in full_dispatch_request
    rv = self.handle_user_exception(e)
  File "C:\Users\lenovo\Envs\yxx_admin\lib\site-packages\flask\app.py", line 1517, in handle_user_exception
    reraise(exc_type, exc_value, tb)
  File "C:\Users\lenovo\Envs\yxx_admin\lib\site-packages\flask\_compat.py", line 33, in reraise
    raise value
  File "C:\Users\lenovo\Envs\yxx_admin\lib\site-packages\flask\app.py", line 1612, in full_dispatch_request
    rv = self.dispatch_request()
  File "C:\Users\lenovo\Envs\yxx_admin\lib\site-packages\flask\app.py", line 1598, in dispatch_request
    return self.view_functions[rule.endpoint](**req.view_args)
  File "D:\py\yxx_admin\apps\home\controller\index.py", line 99, in ajax_get_comments
    return restful.success('请求成功！',data=comments)
  File "D:\py\yxx_admin\think\restful.py", line 13, in success
    return restful_result(code=HttpCode.success,message=message or '请求成功！',data=data,url=url)
  File "D:\py\yxx_admin\think\restful.py", line 10, in restful_result
    return jsonify({"code":code,"info":message,"data":data or {},"url":url})
  File "C:\Users\lenovo\Envs\yxx_admin\lib\site-packages\flask\json.py", line 263, in jsonify
    (dumps(data, indent=indent, separators=separators), '\n'),
  File "C:\Users\lenovo\Envs\yxx_admin\lib\site-packages\flask\json.py", line 123, in dumps
    rv = _json.dumps(obj, **kwargs)
  File "c:\users\lenovo\appdata\local\programs\python\python36\Lib\json\__init__.py", line 238, in dumps
    **kw).encode(obj)
  File "c:\users\lenovo\appdata\local\programs\python\python36\Lib\json\encoder.py", line 199, in encode
    chunks = self.iterencode(o, _one_shot=True)
  File "c:\users\lenovo\appdata\local\programs\python\python36\Lib\json\encoder.py", line 257, in iterencode
    return _iterencode(o, 0)
  File "C:\Users\lenovo\Envs\yxx_admin\lib\site-packages\flask\json.py", line 80, in default
    return _json.JSONEncoder.default(self, o)
  File "c:\users\lenovo\appdata\local\programs\python\python36\Lib\json\encoder.py", line 180, in default
    o.__class__.__name__)
TypeError: Object of type 'Comment' is not JSON serializable
2018-06-16 14:02:03,107 - ERROR - app.py - log_exception - 1560 - Exception on /ajax_get_comments/ [GET]
Traceback (most recent call last):
  File "C:\Users\lenovo\Envs\yxx_admin\lib\site-packages\flask\app.py", line 1982, in wsgi_app
    response = self.full_dispatch_request()
  File "C:\Users\lenovo\Envs\yxx_admin\lib\site-packages\flask\app.py", line 1614, in full_dispatch_request
    rv = self.handle_user_exception(e)
  File "C:\Users\lenovo\Envs\yxx_admin\lib\site-packages\flask\app.py", line 1517, in handle_user_exception
    reraise(exc_type, exc_value, tb)
  File "C:\Users\lenovo\Envs\yxx_admin\lib\site-packages\flask\_compat.py", line 33, in reraise
    raise value
  File "C:\Users\lenovo\Envs\yxx_admin\lib\site-packages\flask\app.py", line 1612, in full_dispatch_request
    rv = self.dispatch_request()
  File "C:\Users\lenovo\Envs\yxx_admin\lib\site-packages\flask\app.py", line 1598, in dispatch_request
    return self.view_functions[rule.endpoint](**req.view_args)
  File "D:\py\yxx_admin\apps\home\controller\index.py", line 99, in ajax_get_comments
    return restful.success('请求成功！',data=comments)
  File "D:\py\yxx_admin\think\restful.py", line 13, in success
    return restful_result(code=HttpCode.success,message=message or '请求成功！',data=data,url=url)
  File "D:\py\yxx_admin\think\restful.py", line 10, in restful_result
    return jsonify({"code":code,"info":message,"data":data or {},"url":url})
  File "C:\Users\lenovo\Envs\yxx_admin\lib\site-packages\flask\json.py", line 263, in jsonify
    (dumps(data, indent=indent, separators=separators), '\n'),
  File "C:\Users\lenovo\Envs\yxx_admin\lib\site-packages\flask\json.py", line 123, in dumps
    rv = _json.dumps(obj, **kwargs)
  File "c:\users\lenovo\appdata\local\programs\python\python36\Lib\json\__init__.py", line 238, in dumps
    **kw).encode(obj)
  File "c:\users\lenovo\appdata\local\programs\python\python36\Lib\json\encoder.py", line 199, in encode
    chunks = self.iterencode(o, _one_shot=True)
  File "c:\users\lenovo\appdata\local\programs\python\python36\Lib\json\encoder.py", line 257, in iterencode
    return _iterencode(o, 0)
  File "C:\Users\lenovo\Envs\yxx_admin\lib\site-packages\flask\json.py", line 80, in default
    return _json.JSONEncoder.default(self, o)
  File "c:\users\lenovo\appdata\local\programs\python\python36\Lib\json\encoder.py", line 180, in default
    o.__class__.__name__)
TypeError: Object of type 'Comment' is not JSON serializable
2018-06-16 14:25:45,256 - ERROR - app.py - log_exception - 1560 - Exception on /ajax_get_comments/ [GET]
Traceback (most recent call last):
  File "C:\Users\lenovo\Envs\yxx_admin\lib\site-packages\flask\app.py", line 1982, in wsgi_app
    response = self.full_dispatch_request()
  File "C:\Users\lenovo\Envs\yxx_admin\lib\site-packages\flask\app.py", line 1614, in full_dispatch_request
    rv = self.handle_user_exception(e)
  File "C:\Users\lenovo\Envs\yxx_admin\lib\site-packages\flask\app.py", line 1517, in handle_user_exception
    reraise(exc_type, exc_value, tb)
  File "C:\Users\lenovo\Envs\yxx_admin\lib\site-packages\flask\_compat.py", line 33, in reraise
    raise value
  File "C:\Users\lenovo\Envs\yxx_admin\lib\site-packages\flask\app.py", line 1612, in full_dispatch_request
    rv = self.dispatch_request()
  File "C:\Users\lenovo\Envs\yxx_admin\lib\site-packages\flask\app.py", line 1598, in dispatch_request
    return self.view_functions[rule.endpoint](**req.view_args)
  File "D:\py\yxx_admin\apps\home\controller\index.py", line 94, in ajax_get_comments
    get_page = request.args('page')
TypeError: 'ImmutableMultiDict' object is not callable
2018-06-16 14:25:54,598 - ERROR - app.py - log_exception - 1560 - Exception on /ajax_get_comments/ [GET]
Traceback (most recent call last):
  File "C:\Users\lenovo\Envs\yxx_admin\lib\site-packages\flask\app.py", line 1982, in wsgi_app
    response = self.full_dispatch_request()
  File "C:\Users\lenovo\Envs\yxx_admin\lib\site-packages\flask\app.py", line 1614, in full_dispatch_request
    rv = self.handle_user_exception(e)
  File "C:\Users\lenovo\Envs\yxx_admin\lib\site-packages\flask\app.py", line 1517, in handle_user_exception
    reraise(exc_type, exc_value, tb)
  File "C:\Users\lenovo\Envs\yxx_admin\lib\site-packages\flask\_compat.py", line 33, in reraise
    raise value
  File "C:\Users\lenovo\Envs\yxx_admin\lib\site-packages\flask\app.py", line 1612, in full_dispatch_request
    rv = self.dispatch_request()
  File "C:\Users\lenovo\Envs\yxx_admin\lib\site-packages\flask\app.py", line 1598, in dispatch_request
    return self.view_functions[rule.endpoint](**req.view_args)
  File "D:\py\yxx_admin\apps\home\controller\index.py", line 94, in ajax_get_comments
    get_page = request.args('page')
TypeError: 'ImmutableMultiDict' object is not callable
2018-06-16 14:26:34,604 - ERROR - app.py - log_exception - 1560 - Exception on /ajax_get_comments/ [GET]
Traceback (most recent call last):
  File "C:\Users\lenovo\Envs\yxx_admin\lib\site-packages\flask\app.py", line 1982, in wsgi_app
    response = self.full_dispatch_request()
  File "C:\Users\lenovo\Envs\yxx_admin\lib\site-packages\flask\app.py", line 1614, in full_dispatch_request
    rv = self.handle_user_exception(e)
  File "C:\Users\lenovo\Envs\yxx_admin\lib\site-packages\flask\app.py", line 1517, in handle_user_exception
    reraise(exc_type, exc_value, tb)
  File "C:\Users\lenovo\Envs\yxx_admin\lib\site-packages\flask\_compat.py", line 33, in reraise
    raise value
  File "C:\Users\lenovo\Envs\yxx_admin\lib\site-packages\flask\app.py", line 1612, in full_dispatch_request
    rv = self.dispatch_request()
  File "C:\Users\lenovo\Envs\yxx_admin\lib\site-packages\flask\app.py", line 1598, in dispatch_request
    return self.view_functions[rule.endpoint](**req.view_args)
  File "D:\py\yxx_admin\apps\home\controller\index.py", line 94, in ajax_get_comments
    get_page = request.args('page')
TypeError: 'ImmutableMultiDict' object is not callable
2018-06-16 14:26:46,811 - ERROR - app.py - log_exception - 1560 - Exception on /ajax_get_comments/ [GET]
Traceback (most recent call last):
  File "C:\Users\lenovo\Envs\yxx_admin\lib\site-packages\flask\app.py", line 1982, in wsgi_app
    response = self.full_dispatch_request()
  File "C:\Users\lenovo\Envs\yxx_admin\lib\site-packages\flask\app.py", line 1614, in full_dispatch_request
    rv = self.handle_user_exception(e)
  File "C:\Users\lenovo\Envs\yxx_admin\lib\site-packages\flask\app.py", line 1517, in handle_user_exception
    reraise(exc_type, exc_value, tb)
  File "C:\Users\lenovo\Envs\yxx_admin\lib\site-packages\flask\_compat.py", line 33, in reraise
    raise value
  File "C:\Users\lenovo\Envs\yxx_admin\lib\site-packages\flask\app.py", line 1612, in full_dispatch_request
    rv = self.dispatch_request()
  File "C:\Users\lenovo\Envs\yxx_admin\lib\site-packages\flask\app.py", line 1598, in dispatch_request
    return self.view_functions[rule.endpoint](**req.view_args)
  File "D:\py\yxx_admin\apps\home\controller\index.py", line 94, in ajax_get_comments
    get_page = request.args('page')
TypeError: 'ImmutableMultiDict' object is not callable
2018-06-16 14:27:56,852 - ERROR - app.py - log_exception - 1560 - Exception on /ajax_get_comments/ [GET]
Traceback (most recent call last):
  File "C:\Users\lenovo\Envs\yxx_admin\lib\site-packages\flask\app.py", line 1982, in wsgi_app
    response = self.full_dispatch_request()
  File "C:\Users\lenovo\Envs\yxx_admin\lib\site-packages\flask\app.py", line 1614, in full_dispatch_request
    rv = self.handle_user_exception(e)
  File "C:\Users\lenovo\Envs\yxx_admin\lib\site-packages\flask\app.py", line 1517, in handle_user_exception
    reraise(exc_type, exc_value, tb)
  File "C:\Users\lenovo\Envs\yxx_admin\lib\site-packages\flask\_compat.py", line 33, in reraise
    raise value
  File "C:\Users\lenovo\Envs\yxx_admin\lib\site-packages\flask\app.py", line 1612, in full_dispatch_request
    rv = self.dispatch_request()
  File "C:\Users\lenovo\Envs\yxx_admin\lib\site-packages\flask\app.py", line 1598, in dispatch_request
    return self.view_functions[rule.endpoint](**req.view_args)
  File "D:\py\yxx_admin\apps\home\controller\index.py", line 94, in ajax_get_comments
    get_page = request.args('page')
TypeError: 'ImmutableMultiDict' object is not callable
2018-06-16 14:28:20,654 - ERROR - app.py - log_exception - 1560 - Exception on /ajax_get_comments/ [GET]
Traceback (most recent call last):
  File "C:\Users\lenovo\Envs\yxx_admin\lib\site-packages\flask\app.py", line 1982, in wsgi_app
    response = self.full_dispatch_request()
  File "C:\Users\lenovo\Envs\yxx_admin\lib\site-packages\flask\app.py", line 1614, in full_dispatch_request
    rv = self.handle_user_exception(e)
  File "C:\Users\lenovo\Envs\yxx_admin\lib\site-packages\flask\app.py", line 1517, in handle_user_exception
    reraise(exc_type, exc_value, tb)
  File "C:\Users\lenovo\Envs\yxx_admin\lib\site-packages\flask\_compat.py", line 33, in reraise
    raise value
  File "C:\Users\lenovo\Envs\yxx_admin\lib\site-packages\flask\app.py", line 1612, in full_dispatch_request
    rv = self.dispatch_request()
  File "C:\Users\lenovo\Envs\yxx_admin\lib\site-packages\flask\app.py", line 1598, in dispatch_request
    return self.view_functions[rule.endpoint](**req.view_args)
  File "D:\py\yxx_admin\apps\home\controller\index.py", line 94, in ajax_get_comments
    get_page = request.args('page')
TypeError: 'ImmutableMultiDict' object is not callable
2018-06-16 14:28:40,672 - ERROR - app.py - log_exception - 1560 - Exception on /ajax_get_comments/ [GET]
Traceback (most recent call last):
  File "C:\Users\lenovo\Envs\yxx_admin\lib\site-packages\flask\app.py", line 1982, in wsgi_app
    response = self.full_dispatch_request()
  File "C:\Users\lenovo\Envs\yxx_admin\lib\site-packages\flask\app.py", line 1614, in full_dispatch_request
    rv = self.handle_user_exception(e)
  File "C:\Users\lenovo\Envs\yxx_admin\lib\site-packages\flask\app.py", line 1517, in handle_user_exception
    reraise(exc_type, exc_value, tb)
  File "C:\Users\lenovo\Envs\yxx_admin\lib\site-packages\flask\_compat.py", line 33, in reraise
    raise value
  File "C:\Users\lenovo\Envs\yxx_admin\lib\site-packages\flask\app.py", line 1612, in full_dispatch_request
    rv = self.dispatch_request()
  File "C:\Users\lenovo\Envs\yxx_admin\lib\site-packages\flask\app.py", line 1598, in dispatch_request
    return self.view_functions[rule.endpoint](**req.view_args)
  File "D:\py\yxx_admin\apps\home\controller\index.py", line 100, in ajax_get_comments
    comments = Comment.query.filter(Comment.post_id == id).order_by('id desc').limit(g.page_size).offset((page-1)*g.page_size).all()
  File "C:\Users\lenovo\Envs\yxx_admin\lib\site-packages\sqlalchemy\orm\query.py", line 2773, in all
    return list(self)
  File "C:\Users\lenovo\Envs\yxx_admin\lib\site-packages\sqlalchemy\orm\query.py", line 2921, in __iter__
    context = self._compile_context()
  File "C:\Users\lenovo\Envs\yxx_admin\lib\site-packages\sqlalchemy\orm\query.py", line 3466, in _compile_context
    context.statement = self._simple_statement(context)
  File "C:\Users\lenovo\Envs\yxx_admin\lib\site-packages\sqlalchemy\orm\query.py", line 3555, in _simple_statement
    **self._select_args
  File "<string>", line 2, in select
  File "C:\Users\lenovo\Envs\yxx_admin\lib\site-packages\sqlalchemy\sql\selectable.py", line 2760, in __init__
    GenerativeSelect.__init__(self, **kwargs)
  File "C:\Users\lenovo\Envs\yxx_admin\lib\site-packages\sqlalchemy\sql\selectable.py", line 1990, in __init__
    self._offset_clause = _offset_or_limit_clause(offset)
  File "C:\Users\lenovo\Envs\yxx_admin\lib\site-packages\sqlalchemy\sql\selectable.py", line 81, in _offset_or_limit_clause
    value = util.asint(element)
  File "C:\Users\lenovo\Envs\yxx_admin\lib\site-packages\sqlalchemy\util\langhelpers.py", line 1018, in asint
    return int(value)
ValueError: invalid literal for int() with base 10: ''
2018-06-16 14:29:25,227 - ERROR - app.py - log_exception - 1560 - Exception on /ajax_get_comments/ [GET]
Traceback (most recent call last):
  File "C:\Users\lenovo\Envs\yxx_admin\lib\site-packages\flask\app.py", line 1982, in wsgi_app
    response = self.full_dispatch_request()
  File "C:\Users\lenovo\Envs\yxx_admin\lib\site-packages\flask\app.py", line 1614, in full_dispatch_request
    rv = self.handle_user_exception(e)
  File "C:\Users\lenovo\Envs\yxx_admin\lib\site-packages\flask\app.py", line 1517, in handle_user_exception
    reraise(exc_type, exc_value, tb)
  File "C:\Users\lenovo\Envs\yxx_admin\lib\site-packages\flask\_compat.py", line 33, in reraise
    raise value
  File "C:\Users\lenovo\Envs\yxx_admin\lib\site-packages\flask\app.py", line 1612, in full_dispatch_request
    rv = self.dispatch_request()
  File "C:\Users\lenovo\Envs\yxx_admin\lib\site-packages\flask\app.py", line 1598, in dispatch_request
    return self.view_functions[rule.endpoint](**req.view_args)
  File "D:\py\yxx_admin\apps\home\controller\index.py", line 99, in ajax_get_comments
    comments = Comment.query.filter(Comment.post_id == id).order_by('id desc').limit(g.page_size).offset((page-1)*g.page_size).all()
  File "C:\Users\lenovo\Envs\yxx_admin\lib\site-packages\sqlalchemy\orm\query.py", line 2773, in all
    return list(self)
  File "C:\Users\lenovo\Envs\yxx_admin\lib\site-packages\sqlalchemy\orm\query.py", line 2921, in __iter__
    context = self._compile_context()
  File "C:\Users\lenovo\Envs\yxx_admin\lib\site-packages\sqlalchemy\orm\query.py", line 3466, in _compile_context
    context.statement = self._simple_statement(context)
  File "C:\Users\lenovo\Envs\yxx_admin\lib\site-packages\sqlalchemy\orm\query.py", line 3555, in _simple_statement
    **self._select_args
  File "<string>", line 2, in select
  File "C:\Users\lenovo\Envs\yxx_admin\lib\site-packages\sqlalchemy\sql\selectable.py", line 2760, in __init__
    GenerativeSelect.__init__(self, **kwargs)
  File "C:\Users\lenovo\Envs\yxx_admin\lib\site-packages\sqlalchemy\sql\selectable.py", line 1990, in __init__
    self._offset_clause = _offset_or_limit_clause(offset)
  File "C:\Users\lenovo\Envs\yxx_admin\lib\site-packages\sqlalchemy\sql\selectable.py", line 81, in _offset_or_limit_clause
    value = util.asint(element)
  File "C:\Users\lenovo\Envs\yxx_admin\lib\site-packages\sqlalchemy\util\langhelpers.py", line 1018, in asint
    return int(value)
ValueError: invalid literal for int() with base 10: ''
2018-06-16 14:30:05,871 - ERROR - app.py - log_exception - 1560 - Exception on /ajax_get_comments/ [GET]
Traceback (most recent call last):
  File "C:\Users\lenovo\Envs\yxx_admin\lib\site-packages\flask\app.py", line 1982, in wsgi_app
    response = self.full_dispatch_request()
  File "C:\Users\lenovo\Envs\yxx_admin\lib\site-packages\flask\app.py", line 1614, in full_dispatch_request
    rv = self.handle_user_exception(e)
  File "C:\Users\lenovo\Envs\yxx_admin\lib\site-packages\flask\app.py", line 1517, in handle_user_exception
    reraise(exc_type, exc_value, tb)
  File "C:\Users\lenovo\Envs\yxx_admin\lib\site-packages\flask\_compat.py", line 33, in reraise
    raise value
  File "C:\Users\lenovo\Envs\yxx_admin\lib\site-packages\flask\app.py", line 1612, in full_dispatch_request
    rv = self.dispatch_request()
  File "C:\Users\lenovo\Envs\yxx_admin\lib\site-packages\flask\app.py", line 1598, in dispatch_request
    return self.view_functions[rule.endpoint](**req.view_args)
  File "D:\py\yxx_admin\apps\home\controller\index.py", line 100, in ajax_get_comments
    comments = Comment.query.filter(Comment.post_id == id).order_by('id desc').limit(g.page_size).offset((page-1)*g.page_size).all()
  File "C:\Users\lenovo\Envs\yxx_admin\lib\site-packages\sqlalchemy\orm\query.py", line 2773, in all
    return list(self)
  File "C:\Users\lenovo\Envs\yxx_admin\lib\site-packages\sqlalchemy\orm\query.py", line 2921, in __iter__
    context = self._compile_context()
  File "C:\Users\lenovo\Envs\yxx_admin\lib\site-packages\sqlalchemy\orm\query.py", line 3466, in _compile_context
    context.statement = self._simple_statement(context)
  File "C:\Users\lenovo\Envs\yxx_admin\lib\site-packages\sqlalchemy\orm\query.py", line 3555, in _simple_statement
    **self._select_args
  File "<string>", line 2, in select
  File "C:\Users\lenovo\Envs\yxx_admin\lib\site-packages\sqlalchemy\sql\selectable.py", line 2760, in __init__
    GenerativeSelect.__init__(self, **kwargs)
  File "C:\Users\lenovo\Envs\yxx_admin\lib\site-packages\sqlalchemy\sql\selectable.py", line 1990, in __init__
    self._offset_clause = _offset_or_limit_clause(offset)
  File "C:\Users\lenovo\Envs\yxx_admin\lib\site-packages\sqlalchemy\sql\selectable.py", line 81, in _offset_or_limit_clause
    value = util.asint(element)
  File "C:\Users\lenovo\Envs\yxx_admin\lib\site-packages\sqlalchemy\util\langhelpers.py", line 1018, in asint
    return int(value)
ValueError: invalid literal for int() with base 10: ''
2018-06-16 14:30:50,215 - ERROR - app.py - log_exception - 1560 - Exception on /ajax_get_comments/ [GET]
Traceback (most recent call last):
  File "C:\Users\lenovo\Envs\yxx_admin\lib\site-packages\flask\app.py", line 1982, in wsgi_app
    response = self.full_dispatch_request()
  File "C:\Users\lenovo\Envs\yxx_admin\lib\site-packages\flask\app.py", line 1614, in full_dispatch_request
    rv = self.handle_user_exception(e)
  File "C:\Users\lenovo\Envs\yxx_admin\lib\site-packages\flask\app.py", line 1517, in handle_user_exception
    reraise(exc_type, exc_value, tb)
  File "C:\Users\lenovo\Envs\yxx_admin\lib\site-packages\flask\_compat.py", line 33, in reraise
    raise value
  File "C:\Users\lenovo\Envs\yxx_admin\lib\site-packages\flask\app.py", line 1612, in full_dispatch_request
    rv = self.dispatch_request()
  File "C:\Users\lenovo\Envs\yxx_admin\lib\site-packages\flask\app.py", line 1598, in dispatch_request
    return self.view_functions[rule.endpoint](**req.view_args)
  File "D:\py\yxx_admin\apps\home\controller\index.py", line 99, in ajax_get_comments
    print(Comment.query.filter(Comment.post_id == id).order_by('id desc').limit(g.page_size).offset((page-1)*g.page_size).all())
  File "C:\Users\lenovo\Envs\yxx_admin\lib\site-packages\sqlalchemy\orm\query.py", line 2773, in all
    return list(self)
  File "C:\Users\lenovo\Envs\yxx_admin\lib\site-packages\sqlalchemy\orm\query.py", line 2921, in __iter__
    context = self._compile_context()
  File "C:\Users\lenovo\Envs\yxx_admin\lib\site-packages\sqlalchemy\orm\query.py", line 3466, in _compile_context
    context.statement = self._simple_statement(context)
  File "C:\Users\lenovo\Envs\yxx_admin\lib\site-packages\sqlalchemy\orm\query.py", line 3555, in _simple_statement
    **self._select_args
  File "<string>", line 2, in select
  File "C:\Users\lenovo\Envs\yxx_admin\lib\site-packages\sqlalchemy\sql\selectable.py", line 2760, in __init__
    GenerativeSelect.__init__(self, **kwargs)
  File "C:\Users\lenovo\Envs\yxx_admin\lib\site-packages\sqlalchemy\sql\selectable.py", line 1990, in __init__
    self._offset_clause = _offset_or_limit_clause(offset)
  File "C:\Users\lenovo\Envs\yxx_admin\lib\site-packages\sqlalchemy\sql\selectable.py", line 81, in _offset_or_limit_clause
    value = util.asint(element)
  File "C:\Users\lenovo\Envs\yxx_admin\lib\site-packages\sqlalchemy\util\langhelpers.py", line 1018, in asint
    return int(value)
ValueError: invalid literal for int() with base 10: ''
2018-06-16 14:32:00,365 - ERROR - app.py - log_exception - 1560 - Exception on /ajax_get_comments/ [GET]
Traceback (most recent call last):
  File "C:\Users\lenovo\Envs\yxx_admin\lib\site-packages\flask\app.py", line 1982, in wsgi_app
    response = self.full_dispatch_request()
  File "C:\Users\lenovo\Envs\yxx_admin\lib\site-packages\flask\app.py", line 1614, in full_dispatch_request
    rv = self.handle_user_exception(e)
  File "C:\Users\lenovo\Envs\yxx_admin\lib\site-packages\flask\app.py", line 1517, in handle_user_exception
    reraise(exc_type, exc_value, tb)
  File "C:\Users\lenovo\Envs\yxx_admin\lib\site-packages\flask\_compat.py", line 33, in reraise
    raise value
  File "C:\Users\lenovo\Envs\yxx_admin\lib\site-packages\flask\app.py", line 1612, in full_dispatch_request
    rv = self.dispatch_request()
  File "C:\Users\lenovo\Envs\yxx_admin\lib\site-packages\flask\app.py", line 1598, in dispatch_request
    return self.view_functions[rule.endpoint](**req.view_args)
  File "D:\py\yxx_admin\apps\home\controller\index.py", line 99, in ajax_get_comments
    print(Comment.query.filter(Comment.post_id == id).limit(g.page_size).offset((page-1)*g.page_size))
  File "C:\Users\lenovo\Envs\yxx_admin\lib\site-packages\sqlalchemy\orm\query.py", line 2928, in __str__
    context = self._compile_context()
  File "C:\Users\lenovo\Envs\yxx_admin\lib\site-packages\sqlalchemy\orm\query.py", line 3466, in _compile_context
    context.statement = self._simple_statement(context)
  File "C:\Users\lenovo\Envs\yxx_admin\lib\site-packages\sqlalchemy\orm\query.py", line 3555, in _simple_statement
    **self._select_args
  File "<string>", line 2, in select
  File "C:\Users\lenovo\Envs\yxx_admin\lib\site-packages\sqlalchemy\sql\selectable.py", line 2760, in __init__
    GenerativeSelect.__init__(self, **kwargs)
  File "C:\Users\lenovo\Envs\yxx_admin\lib\site-packages\sqlalchemy\sql\selectable.py", line 1990, in __init__
    self._offset_clause = _offset_or_limit_clause(offset)
  File "C:\Users\lenovo\Envs\yxx_admin\lib\site-packages\sqlalchemy\sql\selectable.py", line 81, in _offset_or_limit_clause
    value = util.asint(element)
  File "C:\Users\lenovo\Envs\yxx_admin\lib\site-packages\sqlalchemy\util\langhelpers.py", line 1018, in asint
    return int(value)
ValueError: invalid literal for int() with base 10: ''
2018-06-16 14:33:27,212 - ERROR - app.py - log_exception - 1560 - Exception on /ajax_get_comments/ [GET]
Traceback (most recent call last):
  File "C:\Users\lenovo\Envs\yxx_admin\lib\site-packages\flask\app.py", line 1982, in wsgi_app
    response = self.full_dispatch_request()
  File "C:\Users\lenovo\Envs\yxx_admin\lib\site-packages\flask\app.py", line 1614, in full_dispatch_request
    rv = self.handle_user_exception(e)
  File "C:\Users\lenovo\Envs\yxx_admin\lib\site-packages\flask\app.py", line 1517, in handle_user_exception
    reraise(exc_type, exc_value, tb)
  File "C:\Users\lenovo\Envs\yxx_admin\lib\site-packages\flask\_compat.py", line 33, in reraise
    raise value
  File "C:\Users\lenovo\Envs\yxx_admin\lib\site-packages\flask\app.py", line 1612, in full_dispatch_request
    rv = self.dispatch_request()
  File "C:\Users\lenovo\Envs\yxx_admin\lib\site-packages\flask\app.py", line 1598, in dispatch_request
    return self.view_functions[rule.endpoint](**req.view_args)
  File "D:\py\yxx_admin\apps\home\controller\index.py", line 99, in ajax_get_comments
    print(Comment.query.filter(Comment.post_id == id).limit(g.page_size).offset((page-1)*g.page_size).all())
  File "C:\Users\lenovo\Envs\yxx_admin\lib\site-packages\sqlalchemy\orm\query.py", line 2773, in all
    return list(self)
  File "C:\Users\lenovo\Envs\yxx_admin\lib\site-packages\sqlalchemy\orm\query.py", line 2921, in __iter__
    context = self._compile_context()
  File "C:\Users\lenovo\Envs\yxx_admin\lib\site-packages\sqlalchemy\orm\query.py", line 3466, in _compile_context
    context.statement = self._simple_statement(context)
  File "C:\Users\lenovo\Envs\yxx_admin\lib\site-packages\sqlalchemy\orm\query.py", line 3555, in _simple_statement
    **self._select_args
  File "<string>", line 2, in select
  File "C:\Users\lenovo\Envs\yxx_admin\lib\site-packages\sqlalchemy\sql\selectable.py", line 2760, in __init__
    GenerativeSelect.__init__(self, **kwargs)
  File "C:\Users\lenovo\Envs\yxx_admin\lib\site-packages\sqlalchemy\sql\selectable.py", line 1990, in __init__
    self._offset_clause = _offset_or_limit_clause(offset)
  File "C:\Users\lenovo\Envs\yxx_admin\lib\site-packages\sqlalchemy\sql\selectable.py", line 81, in _offset_or_limit_clause
    value = util.asint(element)
  File "C:\Users\lenovo\Envs\yxx_admin\lib\site-packages\sqlalchemy\util\langhelpers.py", line 1018, in asint
    return int(value)
ValueError: invalid literal for int() with base 10: ''
2018-06-16 10:48:11,259 - ERROR - app.py - log_exception - 1560 - Exception on /admin/login/login/ [POST]
Traceback (most recent call last):
  File "/root/.virtualenvs/pfcms/lib/python3.5/site-packages/sqlalchemy/engine/base.py", line 1193, in _execute_context
    context)
  File "/root/.virtualenvs/pfcms/lib/python3.5/site-packages/sqlalchemy/engine/default.py", line 507, in do_execute
    cursor.execute(statement, parameters)
  File "/root/.virtualenvs/pfcms/lib/python3.5/site-packages/pymysql/cursors.py", line 165, in execute
    result = self._query(query)
  File "/root/.virtualenvs/pfcms/lib/python3.5/site-packages/pymysql/cursors.py", line 321, in _query
    conn.query(q)
  File "/root/.virtualenvs/pfcms/lib/python3.5/site-packages/pymysql/connections.py", line 860, in query
    self._affected_rows = self._read_query_result(unbuffered=unbuffered)
  File "/root/.virtualenvs/pfcms/lib/python3.5/site-packages/pymysql/connections.py", line 1061, in _read_query_result
    result.read()
  File "/root/.virtualenvs/pfcms/lib/python3.5/site-packages/pymysql/connections.py", line 1349, in read
    first_packet = self.connection._read_packet()
  File "/root/.virtualenvs/pfcms/lib/python3.5/site-packages/pymysql/connections.py", line 991, in _read_packet
    packet_header = self._read_bytes(4)
  File "/root/.virtualenvs/pfcms/lib/python3.5/site-packages/pymysql/connections.py", line 1037, in _read_bytes
    CR.CR_SERVER_LOST, "Lost connection to MySQL server during query")
pymysql.err.OperationalError: (2013, 'Lost connection to MySQL server during query')

The above exception was the direct cause of the following exception:

Traceback (most recent call last):
  File "/root/.virtualenvs/pfcms/lib/python3.5/site-packages/flask/app.py", line 1982, in wsgi_app
    response = self.full_dispatch_request()
  File "/root/.virtualenvs/pfcms/lib/python3.5/site-packages/flask/app.py", line 1614, in full_dispatch_request
    rv = self.handle_user_exception(e)
  File "/root/.virtualenvs/pfcms/lib/python3.5/site-packages/flask/app.py", line 1517, in handle_user_exception
    reraise(exc_type, exc_value, tb)
  File "/root/.virtualenvs/pfcms/lib/python3.5/site-packages/flask/_compat.py", line 33, in reraise
    raise value
  File "/root/.virtualenvs/pfcms/lib/python3.5/site-packages/flask/app.py", line 1612, in full_dispatch_request
    rv = self.dispatch_request()
  File "/root/.virtualenvs/pfcms/lib/python3.5/site-packages/flask/app.py", line 1598, in dispatch_request
    return self.view_functions[rule.endpoint](**req.view_args)
  File "/root/.virtualenvs/pfcms/lib/python3.5/site-packages/flask/views.py", line 84, in view
    return self.dispatch_request(*args, **kwargs)
  File "/root/.virtualenvs/pfcms/lib/python3.5/site-packages/flask/views.py", line 149, in dispatch_request
    return meth(*args, **kwargs)
  File "./apps/admin/controller/login.py", line 22, in post
    admin_data = Admin.query.filter(Admin.account == account).first()
  File "/root/.virtualenvs/pfcms/lib/python3.5/site-packages/sqlalchemy/orm/query.py", line 2825, in first
    ret = list(self[0:1])
  File "/root/.virtualenvs/pfcms/lib/python3.5/site-packages/sqlalchemy/orm/query.py", line 2617, in __getitem__
    return list(res)
  File "/root/.virtualenvs/pfcms/lib/python3.5/site-packages/sqlalchemy/orm/query.py", line 2925, in __iter__
    return self._execute_and_instances(context)
  File "/root/.virtualenvs/pfcms/lib/python3.5/site-packages/sqlalchemy/orm/query.py", line 2948, in _execute_and_instances
    result = conn.execute(querycontext.statement, self._params)
  File "/root/.virtualenvs/pfcms/lib/python3.5/site-packages/sqlalchemy/engine/base.py", line 948, in execute
    return meth(self, multiparams, params)
  File "/root/.virtualenvs/pfcms/lib/python3.5/site-packages/sqlalchemy/sql/elements.py", line 269, in _execute_on_connection
    return connection._execute_clauseelement(self, multiparams, params)
  File "/root/.virtualenvs/pfcms/lib/python3.5/site-packages/sqlalchemy/engine/base.py", line 1060, in _execute_clauseelement
    compiled_sql, distilled_params
  File "/root/.virtualenvs/pfcms/lib/python3.5/site-packages/sqlalchemy/engine/base.py", line 1200, in _execute_context
    context)
  File "/root/.virtualenvs/pfcms/lib/python3.5/site-packages/sqlalchemy/engine/base.py", line 1413, in _handle_dbapi_exception
    exc_info
  File "/root/.virtualenvs/pfcms/lib/python3.5/site-packages/sqlalchemy/util/compat.py", line 203, in raise_from_cause
    reraise(type(exception), exception, tb=exc_tb, cause=cause)
  File "/root/.virtualenvs/pfcms/lib/python3.5/site-packages/sqlalchemy/util/compat.py", line 186, in reraise
    raise value.with_traceback(tb)
  File "/root/.virtualenvs/pfcms/lib/python3.5/site-packages/sqlalchemy/engine/base.py", line 1193, in _execute_context
    context)
  File "/root/.virtualenvs/pfcms/lib/python3.5/site-packages/sqlalchemy/engine/default.py", line 507, in do_execute
    cursor.execute(statement, parameters)
  File "/root/.virtualenvs/pfcms/lib/python3.5/site-packages/pymysql/cursors.py", line 165, in execute
    result = self._query(query)
  File "/root/.virtualenvs/pfcms/lib/python3.5/site-packages/pymysql/cursors.py", line 321, in _query
    conn.query(q)
  File "/root/.virtualenvs/pfcms/lib/python3.5/site-packages/pymysql/connections.py", line 860, in query
    self._affected_rows = self._read_query_result(unbuffered=unbuffered)
  File "/root/.virtualenvs/pfcms/lib/python3.5/site-packages/pymysql/connections.py", line 1061, in _read_query_result
    result.read()
  File "/root/.virtualenvs/pfcms/lib/python3.5/site-packages/pymysql/connections.py", line 1349, in read
    first_packet = self.connection._read_packet()
  File "/root/.virtualenvs/pfcms/lib/python3.5/site-packages/pymysql/connections.py", line 991, in _read_packet
    packet_header = self._read_bytes(4)
  File "/root/.virtualenvs/pfcms/lib/python3.5/site-packages/pymysql/connections.py", line 1037, in _read_bytes
    CR.CR_SERVER_LOST, "Lost connection to MySQL server during query")
sqlalchemy.exc.OperationalError: (pymysql.err.OperationalError) (2013, 'Lost connection to MySQL server during query') [SQL: 'SELECT tb_admin.id AS tb_admin_id, tb_admin.admin_name AS tb_admin_admin_name, tb_admin._password AS tb_admin__password, tb_admin.img AS tb_admin_img, tb_admin.account AS tb_admin_account, tb_admin.sex AS tb_admin_sex, tb_admin.state AS tb_admin_state, tb_admin._last_time AS tb_admin__last_time, tb_admin._create_time AS tb_admin__create_time \nFROM tb_admin \nWHERE tb_admin.account = %(account_1)s \n LIMIT %(param_1)s'] [parameters: {'param_1': 1, 'account_1': '666666'}] (Background on this error at: http://sqlalche.me/e/e3q8)
